[ 2023-03-19 13:07:07,209 ] 224 werkzeug - INFO - [31m[1mWARNING: This is a development server. Do not use it in a production deployment. Use a production WSGI server instead.[0m
 * Running on all addresses (0.0.0.0)
 * Running on http://127.0.0.1:5000
 * Running on http://192.168.29.242:5000
[ 2023-03-19 13:07:07,210 ] 224 werkzeug - INFO - [33mPress CTRL+C to quit[0m
[ 2023-03-19 13:07:10,595 ] 224 werkzeug - INFO - 127.0.0.1 - - [19/Mar/2023 13:07:10] "GET / HTTP/1.1" 200 -
[ 2023-03-19 13:07:17,932 ] 224 werkzeug - INFO - 127.0.0.1 - - [19/Mar/2023 13:07:17] "GET /predictdata HTTP/1.1" 200 -
[ 2023-03-19 13:07:30,481 ] 1744 app - ERROR - Exception on /predictdata [POST]
Traceback (most recent call last):
  File "C:\Users\CSC\anaconda3\envs\project\lib\site-packages\flask\app.py", line 2528, in wsgi_app
    response = self.full_dispatch_request()
  File "C:\Users\CSC\anaconda3\envs\project\lib\site-packages\flask\app.py", line 1825, in full_dispatch_request
    rv = self.handle_user_exception(e)
  File "C:\Users\CSC\anaconda3\envs\project\lib\site-packages\flask\app.py", line 1823, in full_dispatch_request
    rv = self.dispatch_request()
  File "C:\Users\CSC\anaconda3\envs\project\lib\site-packages\flask\app.py", line 1799, in dispatch_request
    return self.ensure_sync(self.view_functions[rule.endpoint])(**view_args)
  File "app.py", line 33, in predict_datapoint
    pred_df=data.get_data_as_data_frame()
AttributeError: 'CustomData' object has no attribute 'get_data_as_data_frame'
[ 2023-03-19 13:07:30,482 ] 224 werkzeug - INFO - 127.0.0.1 - - [19/Mar/2023 13:07:30] "[35m[1mPOST /predictdata HTTP/1.1[0m" 500 -
